Traceback (most recent call last):
  File "/opt/conda/lib/python3.10/site-packages/jupyter_cache/executors/utils.py", line 51, in single_nb_execution
    executenb(
  File "/opt/conda/lib/python3.10/site-packages/nbclient/client.py", line 1204, in execute
    return NotebookClient(nb=nb, resources=resources, km=km, **kwargs).execute()
  File "/opt/conda/lib/python3.10/site-packages/nbclient/util.py", line 84, in wrapped
    return just_run(coro(*args, **kwargs))
  File "/opt/conda/lib/python3.10/site-packages/nbclient/util.py", line 62, in just_run
    return loop.run_until_complete(coro)
  File "/opt/conda/lib/python3.10/asyncio/base_events.py", line 646, in run_until_complete
    return future.result()
  File "/opt/conda/lib/python3.10/site-packages/nbclient/client.py", line 663, in async_execute
    await self.async_execute_cell(
  File "/opt/conda/lib/python3.10/site-packages/nbclient/client.py", line 965, in async_execute_cell
    await self._check_raise_for_error(cell, cell_index, exec_reply)
  File "/opt/conda/lib/python3.10/site-packages/nbclient/client.py", line 862, in _check_raise_for_error
    raise CellExecutionError.from_cell_and_msg(cell, exec_reply_content)
nbclient.exceptions.CellExecutionError: An error occurred while executing the following cell:
------------------
from jupyterquiz import display_quiz
display_quiz("../quizzes/fs.json", colors="fdsp")
------------------

[0;31m---------------------------------------------------------------------------[0m
[0;31mTypeError[0m                                 Traceback (most recent call last)
Input [0;32mIn [1][0m, in [0;36m<cell line: 2>[0;34m()[0m
[1;32m      1[0m [38;5;28;01mfrom[39;00m [38;5;21;01mjupyterquiz[39;00m [38;5;28;01mimport[39;00m display_quiz
[0;32m----> 2[0m [43mdisplay_quiz[49m[43m([49m[38;5;124;43m"[39;49m[38;5;124;43m../quizzes/fs.json[39;49m[38;5;124;43m"[39;49m[43m,[49m[43m [49m[43mcolors[49m[38;5;241;43m=[39;49m[38;5;124;43m"[39;49m[38;5;124;43mfdsp[39;49m[38;5;124;43m"[39;49m[43m)[49m

[0;31mTypeError[0m: display_quiz() got an unexpected keyword argument 'colors'
TypeError: display_quiz() got an unexpected keyword argument 'colors'

